Workbook

Sheet Synthèse
A1: Nom du projet | B1: Ma super SAE de folie sur laquelle je vais consacrer tout mon semestre ^^ | D1: Nom étudiant | E1: Prénom étudiant
A2: Nom du tuteur | B2: Notre tuteur | D2: Nom1 | E2: Prénom1
D3: Nom2 | E3: Prénom2
D4: Nom3 | E4: Prénom3
D5: Nom4 | E5: Prénom4
A7: Bilan de la répartation du travail depuis le début du développement
C8: =D2 -> Nom1 | D8: =D3 -> Nom2 | E8: =D4 -> Nom3 | F8: =D5 -> Nom4 | G8: Total
A9: Séance 5 | B9: Nombre d'heures travaillées | C9: ='Séance 5'!B26 -> 0 | D9: ='Séance 5'!C26 -> 0 | E9: ='Séance 5'!D26 -> 0 | F9: ='Séance 5'!E26 -> 0 | G9: ='Séance 5'!G26 -> 0
B10: Répartation en pourcentage | C10: ='Séance 5'!B27 -> Non renseigné | D10: ='Séance 5'!C27 -> Non renseigné | E10: ='Séance 5'!D27 -> Non renseigné | F10: ='Séance 5'!E27 -> Non renseigné
A11: Séance 6 | B11: Nombre d'heures travaillées | C11: ='Séance 6'!B26 -> 0 | D11: ='Séance 6'!V26 -> 0 | E11: ='Séance 6'!E26 -> 0 | F11: ='Séance 6'!E26 -> 0 | G11: ='Séance 6'!G25 -> 0
B12: Répartation en pourcentage | C12: ='Séance 6'!B27 -> Non renseigné | D12: ='Séance 6'!C27 -> Non renseigné | E12: ='Séance 6'!D27 -> Non renseigné | F12: ='Séance 6'!E27 -> Non renseigné
A13: Séance 7 | B13: Nombre d'heures travaillées | C13: ='Séance 7'!B26 -> 0 | D13: ='Séance 7'!C26 -> 0 | E13: ='Séance 7'!D26 -> 0 | F13: ='Séance 7'!E26 -> 0 | G13: ='Séance 7'!G25 -> 0
B14: Répartation en pourcentage | C14: ='Séance 7'!B27 -> Non renseigné | D14: ='Séance 7'!C27 -> Non renseigné | E14: ='Séance 7'!D27 -> Non renseigné | F14: ='Séance 7'!E27 -> Non renseigné
A15: Séance 8 | B15: Nombre d'heures travaillées | C15: ='Séance 8'!B26 -> 0 | D15: ='Séance 8'!C26 -> 0 | E15: ='Séance 8'!D26 -> 0 | F15: ='Séance 8'!E26 -> 0 | G15: ='Séance 8'!G25 -> 0
B16: Répartation en pourcentage | C16: ='Séance 8'!B27 -> Non renseigné | D16: ='Séance 8'!C27 -> Non renseigné | E16: ='Séance 8'!D27 -> Non renseigné | F16: ='Séance 8'!E27 -> Non renseigné
A17: Séance 9 | B17: Nombre d'heures travaillées | C17: ='Séance 9'!B26 -> 0 | D17: ='Séance 9'!C26 -> 0 | E17: ='Séance 9'!D26 -> 0 | F17: ='Séance 9'!E26 -> 0 | G17: ='Séance 9'!G25 -> 0
B18: Répartation en pourcentage | C18: ='Séance 9'!B27 -> Non renseigné | D18: ='Séance 9'!C27 -> Non renseigné | E18: ='Séance 9'!D27 -> Non renseigné | F18: ='Séance 9'!E27 -> Non renseigné
A19: Moyenne de travail par séance | C19: =IF(COUNT('Séance 5'!B27,'Séance 6'!C26,'Séance 7'!C26,'Séance 8'!C26,'Séance 9'!C26)=0,"Non renseigné",(IF('Séance 5'!B27="Non renseigné",0,'Séance 5'!B27) +IF('Séance 6'!C26="Non renseigné",0,'Séance 6'!C26) +IF('Séance 7'!C26="Non renseigné",0,'Séance 7'!C26) +IF('Séance 8'!C26="Non renseigné",0,'Séance 8'!C26) +IF('Séance 9'!C26="Non renseigné",0,'Séance 9'!C26) ) /( COUNT('Séance 5'!B27,'Séance 6'!C26,'Séance 7'!C26,'Séance 8'!C26,'Séance 9'!C26))) -> 0 | D19: =IF(COUNT('Séance 5'!B27,'Séance 6'!C26,'Séance 7'!C26,'Séance 8'!C26,'Séance 9'!C26)=0,"Non renseigné",(IF('Séance 5'!C27="Non renseigné",0,'Séance 5'!C27) +IF('Séance 6'!D26="Non renseigné",0,'Séance 6'!D26) +IF('Séance 7'!D26="Non renseigné",0,'Séance 7'!D26) +IF('Séance 8'!D26="Non renseigné",0,'Séance 8'!D26) +IF('Séance 9'!D26="Non renseigné",0,'Séance 9'!D26) ) /( COUNT('Séance 5'!C27,'Séance 6'!D26,'Séance 7'!D26,'Séance 8'!D26,'Séance 9'!D26))) -> 0 | E19: =IF(COUNT('Séance 5'!B27,'Séance 6'!C26,'Séance 7'!C26,'Séance 8'!C26,'Séance 9'!C26)=0,"Non renseigné",(IF('Séance 5'!D27="Non renseigné",0,'Séance 5'!D27) +IF('Séance 6'!E26="Non renseigné",0,'Séance 6'!E26) +IF('Séance 7'!E26="Non renseigné",0,'Séance 7'!E26) +IF('Séance 8'!E26="Non renseigné",0,'Séance 8'!E26) +IF('Séance 9'!E26="Non renseigné",0,'Séance 9'!E26) ) /( COUNT('Séance 5'!D27,'Séance 6'!E26,'Séance 7'!E26,'Séance 8'!E26,'Séance 9'!E26))) -> 0 | F19: =IF(COUNT('Séance 5'!B27,'Séance 6'!C26,'Séance 7'!C26,'Séance 8'!C26,'Séance 9'!C26)=0,"Non renseigné",(IF('Séance 5'!E27="Non renseigné",0,'Séance 5'!E27) +IF('Séance 6'!F26="Non renseigné",0,'Séance 6'!F26) +IF('Séance 7'!F26="Non renseigné",0,'Séance 7'!F26) +IF('Séance 8'!F26="Non renseigné",0,'Séance 8'!F26) +IF('Séance 9'!F26="Non renseigné",0,'Séance 9'!F26) ) /( COUNT('Séance 5'!E27,'Séance 6'!F26,'Séance 7'!F26,'Séance 8'!F26,'Séance 9'!F26))) -> 0
A20: Temps de travail global | B20: Nombre d'heures travaillées | C20: =C9+C11+C13+C15+C17 -> 0 | D20: =D9+D11+D13+D15+D17 -> 0 | E20: =E9+E11+E13+E15+E17 -> 0 | F20: =F9+F11+F13+F15+F17 -> 0 | G20: =G9+G11+G13+G15+G17 -> 0
B21: Répartation en pourcentage | C21: =IF(G20=0,"Non renseigné",C20/G20*100) -> Non renseigné | D21: =IF(H22=0,"Non renseigné",D20/H22*100) -> Non renseigné | E21: =IF(I22=0,"Non renseigné",E20/I22*100) -> Non renseigné | F21: =IF(J22=0,"Non renseigné",F20/J22*100) -> Non renseigné

Sheet Séance 4
A1: Tâches prévues | B1: =Synthèse!$D2 -> Nom1 | C1: =Synthèse!$D3 -> Nom2 | D1: =Synthèse!$D4 -> Nom3 | E1: =Synthèse!$D5 -> Nom4
A2: Description de la tâche | B2: Durée estimée | C2: Durée estimée2 | D2: Durée estimée3 | E2: Durée estimée4 | F2: Durée totale estimée (heures)
F3: =SUM(Tableau142527[[#This Row],[Durée estimée]:[Durée estimée4]]) -> 0
F4: =SUM(Tableau142527[[#This Row],[Durée estimée]:[Durée estimée4]]) -> 0
F5: =SUM(Tableau142527[[#This Row],[Durée estimée]:[Durée estimée4]]) -> 0
F6: =SUM(Tableau142527[[#This Row],[Durée estimée]:[Durée estimée4]]) -> 0
F7: =SUM(Tableau142527[[#This Row],[Durée estimée]:[Durée estimée4]]) -> 0
F8: =SUM(Tableau142527[[#This Row],[Durée estimée]:[Durée estimée4]]) -> 0
F9: =SUM(Tableau142527[[#This Row],[Durée estimée]:[Durée estimée4]]) -> 0
F10: =SUM(Tableau142527[[#This Row],[Durée estimée]:[Durée estimée4]]) -> 0
F11: =SUM(Tableau142527[[#This Row],[Durée estimée]:[Durée estimée4]]) -> 0
F12: =SUM(Tableau142527[[#This Row],[Durée estimée]:[Durée estimée4]]) -> 0
F13: =SUM(Tableau142527[[#This Row],[Durée estimée]:[Durée estimée4]]) -> 0
F14: =SUM(Tableau142527[[#This Row],[Durée estimée]:[Durée estimée4]]) -> 0
... F25: =SUM(Tableau142527[[#This Row],[Durée estimée]:[Durée estimée4]]) -> 0
A26: Volume global prévu | B26: =SUM(B3:B25) -> 0 | C26: =SUM(C3:C25) -> 0 | D26: =SUM(D3:D25) -> 0 | E26: =SUM(E3:E25) -> 0 | F26: =SUM(F3:F25) -> 0
A27: Pourcentage global prévu | B27: =IF($F$26=0,"Non renseigné",B26/$F$26*100) -> Non renseigné | C27: =IF($F$26=0,"Non renseigné",C26/$F$26*100) -> Non renseigné | D27: =IF($F$26=0,"Non renseigné",D26/$F$26*100) -> Non renseigné | E27: =IF($F$26=0,"Non renseigné",E26/$F$26*100) -> Non renseigné | F27: =SUM(Tableau142527[[#This Row],[Durée estimée]:[Durée estimée4]]) -> 0

Sheet Séance 5
A1: Bilan des tâches réalisées | B1: =Synthèse!D2 -> Nom1 | C1: =Synthèse!D3 -> Nom2 | D1: =Synthèse!D4 -> Nom3 | E1: =Synthèse!D5 -> Nom4 | I1: Tâches prévues | J1: =Synthèse!$D2 -> Nom1 | K1: =Synthèse!$D3 -> Nom2 | L1: =Synthèse!$D4 -> Nom3 | M1: =Synthèse!$D5 -> Nom4
A2: Description de la tâche | B2: Durée réelle en heures | C2: Durée réelle en heures2 | D2: Durée réelle en heures3 | E2: Durée réelle en heures4 | F2: Total réel | G2: Ecart relatif entre prévisionnel et réel | I2: Description de la tâche | J2: Durée estimée | K2: Durée estimée2 | L2: Durée estimée3 | M2: Durée estimée4 | N2: Durée totale estimée (heures)
A3: =IF(ISBLANK(Tableau142527[[#This Row],[Description de la tâche]]),"",Tableau142527[[#This Row],[Description de la tâche]]) | B3: =IF(ISBLANK(Tableau142527[[#This Row],[Durée estimée]]),"",Tableau142527[[#This Row],[Durée estimée]]) | C3: =IF(ISBLANK(Tableau142527[[#This Row],[Durée estimée2]]),"",Tableau142527[[#This Row],[Durée estimée2]]) | D3: =IF(ISBLANK(Tableau142527[[#This Row],[Durée estimée3]]),"",Tableau142527[[#This Row],[Durée estimée3]]) | E3: =IF(ISBLANK(Tableau142527[[#This Row],[Durée estimée4]]),"",Tableau142527[[#This Row],[Durée estimée4]]) | F3: =SUM(Tableau132628[[#This Row],[Durée réelle en heures]:[Durée réelle en heures4]]) -> 0 | G3: =IF('Séance 5'!F3=0,0,IF('Séance 4'!F3=0,"Nouvelle tâche",(('Séance 5'!F3)/'Séance 4'!F3))) -> 0 | N3: =SUM(Tableau14252729[[#This Row],[Durée estimée]:[Durée estimée4]]) -> 0
A4: =IF(ISBLANK(Tableau142527[[#This Row],[Description de la tâche]]),"",Tableau142527[[#This Row],[Description de la tâche]]) | B4: =IF(ISBLANK(Tableau142527[[#This Row],[Durée estimée]]),"",Tableau142527[[#This Row],[Durée estimée]]) | C4: =IF(ISBLANK(Tableau142527[[#This Row],[Durée estimée2]]),"",Tableau142527[[#This Row],[Durée estimée2]]) | D4: =IF(ISBLANK(Tableau142527[[#This Row],[Durée estimée3]]),"",Tableau142527[[#This Row],[Durée estimée3]]) | E4: =IF(ISBLANK(Tableau142527[[#This Row],[Durée estimée4]]),"",Tableau142527[[#This Row],[Durée estimée4]]) | F4: =SUM(Tableau132628[[#This Row],[Durée réelle en heures]:[Durée réelle en heures4]]) -> 0 | G4: =IF('Séance 5'!F4=0,0,IF('Séance 4'!F4=0,"Nouvelle tâche",(('Séance 5'!F4)/'Séance 4'!F4))) -> 0 | N4: =SUM(Tableau14252729[[#This Row],[Durée estimée]:[Durée estimée4]]) -> 0
A5: =IF(ISBLANK(Tableau142527[[#This Row],[Description de la tâche]]),"",Tableau142527[[#This Row],[Description de la tâche]]) | B5: =IF(ISBLANK(Tableau142527[[#This Row],[Durée estimée]]),"",Tableau142527[[#This Row],[Durée estimée]]) | C5: =IF(ISBLANK(Tableau142527[[#This Row],[Durée estimée2]]),"",Tableau142527[[#This Row],[Durée estimée2]]) | D5: =IF(ISBLANK(Tableau142527[[#This Row],[Durée estimée3]]),"",Tableau142527[[#This Row],[Durée estimée3]]) | E5: =IF(ISBLANK(Tableau142527[[#This Row],[Durée estimée4]]),"",Tableau142527[[#This Row],[Durée estimée4]]) | F5: =SUM(Tableau132628[[#This Row],[Durée réelle en heures]:[Durée réelle en heures4]]) -> 0 | G5: =IF('Séance 5'!F5=0,0,IF('Séance 4'!F5=0,"Nouvelle tâche",(('Séance 5'!F5)/'Séance 4'!F5))) -> 0 | N5: =SUM(Tableau14252729[[#This Row],[Durée estimée]:[Durée estimée4]]) -> 0
A6: =IF(ISBLANK(Tableau142527[[#This Row],[Description de la tâche]]),"",Tableau142527[[#This Row],[Description de la tâche]]) | B6: =IF(ISBLANK(Tableau142527[[#This Row],[Durée estimée]]),"",Tableau142527[[#This Row],[Durée estimée]]) | C6: =IF(ISBLANK(Tableau142527[[#This Row],[Durée estimée2]]),"",Tableau142527[[#This Row],[Durée estimée2]]) | D6: =IF(ISBLANK(Tableau142527[[#This Row],[Durée estimée3]]),"",Tableau142527[[#This Row],[Durée estimée3]]) | E6: =IF(ISBLANK(Tableau142527[[#This Row],[Durée estimée4]]),"",Tableau142527[[#This Row],[Durée estimée4]]) | F6: =SUM(Tableau132628[[#This Row],[Durée réelle en heures]:[Durée réelle en heures4]]) -> 0 | G6: =IF('Séance 5'!F6=0,0,IF('Séance 4'!F6=0,"Nouvelle tâche",(('Séance 5'!F6)/'Séance 4'!F6))) -> 0 | N6: =SUM(Tableau14252729[[#This Row],[Durée estimée]:[Durée estimée4]]) -> 0
A7: =IF(ISBLANK(Tableau142527[[#This Row],[Description de la tâche]]),"",Tableau142527[[#This Row],[Description de la tâche]]) | B7: =IF(ISBLANK(Tableau142527[[#This Row],[Durée estimée]]),"",Tableau142527[[#This Row],[Durée estimée]]) | C7: =IF(ISBLANK(Tableau142527[[#This Row],[Durée estimée2]]),"",Tableau142527[[#This Row],[Durée estimée2]]) | D7: =IF(ISBLANK(Tableau142527[[#This Row],[Durée estimée3]]),"",Tableau142527[[#This Row],[Durée estimée3]]) | E7: =IF(ISBLANK(Tableau142527[[#This Row],[Durée estimée4]]),"",Tableau142527[[#This Row],[Durée estimée4]]) | F7: =SUM(Tableau132628[[#This Row],[Durée réelle en heures]:[Durée réelle en heures4]]) -> 0 | G7: =IF('Séance 5'!F7=0,0,IF('Séance 4'!F7=0,"Nouvelle tâche",(('Séance 5'!F7)/'Séance 4'!F7))) -> 0 | N7: =SUM(Tableau14252729[[#This Row],[Durée estimée]:[Durée estimée4]]) -> 0
A8: =IF(ISBLANK(Tableau142527[[#This Row],[Description de la tâche]]),"",Tableau142527[[#This Row],[Description de la tâche]]) | B8: =IF(ISBLANK(Tableau142527[[#This Row],[Durée estimée]]),"",Tableau142527[[#This Row],[Durée estimée]]) | C8: =IF(ISBLANK(Tableau142527[[#This Row],[Durée estimée2]]),"",Tableau142527[[#This Row],[Durée estimée2]]) | D8: =IF(ISBLANK(Tableau142527[[#This Row],[Durée estimée3]]),"",Tableau142527[[#This Row],[Durée estimée3]]) | E8: =IF(ISBLANK(Tableau142527[[#This Row],[Durée estimée4]]),"",Tableau142527[[#This Row],[Durée estimée4]]) | F8: =SUM(Tableau132628[[#This Row],[Durée réelle en heures]:[Durée réelle en heures4]]) -> 0 | G8: =IF('Séance 5'!F8=0,0,IF('Séance 4'!F8=0,"Nouvelle tâche",(('Séance 5'!F8)/'Séance 4'!F8))) -> 0 | N8: =SUM(Tableau14252729[[#This Row],[Durée estimée]:[Durée estimée4]]) -> 0
A9: =IF(ISBLANK(Tableau142527[[#This Row],[Description de la tâche]]),"",Tableau142527[[#This Row],[Description de la tâche]]) | B9: =IF(ISBLANK(Tableau142527[[#This Row],[Durée estimée]]),"",Tableau142527[[#This Row],[Durée estimée]]) | C9: =IF(ISBLANK(Tableau142527[[#This Row],[Durée estimée2]]),"",Tableau142527[[#This Row],[Durée estimée2]]) | D9: =IF(ISBLANK(Tableau142527[[#This Row],[Durée estimée3]]),"",Tableau142527[[#This Row],[Durée estimée3]]) | E9: =IF(ISBLANK(Tableau142527[[#This Row],[Durée estimée4]]),"",Tableau142527[[#This Row],[Durée estimée4]]) | F9: =SUM(Tableau132628[[#This Row],[Durée réelle en heures]:[Durée réelle en heures4]]) -> 0 | G9: =IF('Séance 5'!F9=0,0,IF('Séance 4'!F9=0,"Nouvelle tâche",(('Séance 5'!F9)/'Séance 4'!F9))) -> 0 | N9: =SUM(Tableau14252729[[#This Row],[Durée estimée]:[Durée estimée4]]) -> 0
A10: =IF(ISBLANK(Tableau142527[[#This Row],[Description de la tâche]]),"",Tableau142527[[#This Row],[Description de la tâche]]) | B10: =IF(ISBLANK(Tableau142527[[#This Row],[Durée estimée]]),"",Tableau142527[[#This Row],[Durée estimée]]) | C10: =IF(ISBLANK(Tableau142527[[#This Row],[Durée estimée2]]),"",Tableau142527[[#This Row],[Durée estimée2]]) | D10: =IF(ISBLANK(Tableau142527[[#This Row],[Durée estimée3]]),"",Tableau142527[[#This Row],[Durée estimée3]]) | E10: =IF(ISBLANK(Tableau142527[[#This Row],[Durée estimée4]]),"",Tableau142527[[#This Row],[Durée estimée4]]) | F10: =SUM(Tableau132628[[#This Row],[Durée réelle en heures]:[Durée réelle en heures4]]) -> 0 | G10: =IF('Séance 5'!F10=0,0,IF('Séance 4'!F10=0,"Nouvelle tâche",(('Séance 5'!F10)/'Séance 4'!F10))) -> 0 | N10: =SUM(Tableau14252729[[#This Row],[Durée estimée]:[Durée estimée4]]) -> 0
A11: =IF(ISBLANK(Tableau142527[[#This Row],[Description de la tâche]]),"",Tableau142527[[#This Row],[Description de la tâche]]) | B11: =IF(ISBLANK(Tableau142527[[#This Row],[Durée estimée]]),"",Tableau142527[[#This Row],[Durée estimée]]) | C11: =IF(ISBLANK(Tableau142527[[#This Row],[Durée estimée2]]),"",Tableau142527[[#This Row],[Durée estimée2]]) | D11: =IF(ISBLANK(Tableau142527[[#This Row],[Durée estimée3]]),"",Tableau142527[[#This Row],[Durée estimée3]]) | E11: =IF(ISBLANK(Tableau142527[[#This Row],[Durée estimée4]]),"",Tableau142527[[#This Row],[Durée estimée4]]) | F11: =SUM(Tableau132628[[#This Row],[Durée réelle en heures]:[Durée réelle en heures4]]) -> 0 | G11: =IF('Séance 5'!F11=0,0,IF('Séance 4'!F11=0,"Nouvelle tâche",(('Séance 5'!F11)/'Séance 4'!F11))) -> 0 | N11: =SUM(Tableau14252729[[#This Row],[Durée estimée]:[Durée estimée4]]) -> 0
A12: =IF(ISBLANK(Tableau142527[[#This Row],[Description de la tâche]]),"",Tableau142527[[#This Row],[Description de la tâche]]) | B12: =IF(ISBLANK(Tableau142527[[#This Row],[Durée estimée]]),"",Tableau142527[[#This Row],[Durée estimée]]) | C12: =IF(ISBLANK(Tableau142527[[#This Row],[Durée estimée2]]),"",Tableau142527[[#This Row],[Durée estimée2]]) | D12: =IF(ISBLANK(Tableau142527[[#This Row],[Durée estimée3]]),"",Tableau142527[[#This Row],[Durée estimée3]]) | E12: =IF(ISBLANK(Tableau142527[[#This Row],[Durée estimée4]]),"",Tableau142527[[#This Row],[Durée estimée4]]) | F12: =SUM(Tableau132628[[#This Row],[Durée réelle en heures]:[Durée réelle en heures4]]) -> 0 | G12: =IF('Séance 5'!F12=0,0,IF('Séance 4'!F12=0,"Nouvelle tâche",(('Séance 5'!F12)/'Séance 4'!F12))) -> 0 | N12: =SUM(Tableau14252729[[#This Row],[Durée estimée]:[Durée estimée4]]) -> 0
A13: =IF(ISBLANK(Tableau142527[[#This Row],[Description de la tâche]]),"",Tableau142527[[#This Row],[Description de la tâche]]) | B13: =IF(ISBLANK(Tableau142527[[#This Row],[Durée estimée]]),"",Tableau142527[[#This Row],[Durée estimée]]) | C13: =IF(ISBLANK(Tableau142527[[#This Row],[Durée estimée2]]),"",Tableau142527[[#This Row],[Durée estimée2]]) | D13: =IF(ISBLANK(Tableau142527[[#This Row],[Durée estimée3]]),"",Tableau142527[[#This Row],[Durée estimée3]]) | E13: =IF(ISBLANK(Tableau142527[[#This Row],[Durée estimée4]]),"",Tableau142527[[#This Row],[Durée estimée4]]) | F13: =SUM(Tableau132628[[#This Row],[Durée réelle en heures]:[Durée réelle en heures4]]) -> 0 | G13: =IF('Séance 5'!F13=0,0,IF('Séance 4'!F13=0,"Nouvelle tâche",(('Séance 5'!F13)/'Séance 4'!F13))) -> 0 | N13: =SUM(Tableau14252729[[#This Row],[Durée estimée]:[Durée estimée4]]) -> 0
A14: =IF(ISBLANK(Tableau142527[[#This Row],[Description de la tâche]]),"",Tableau142527[[#This Row],[Description de la tâche]]) | B14: =IF(ISBLANK(Tableau142527[[#This Row],[Durée estimée]]),"",Tableau142527[[#This Row],[Durée estimée]]) | C14: =IF(ISBLANK(Tableau142527[[#This Row],[Durée estimée2]]),"",Tableau142527[[#This Row],[Durée estimée2]]) | D14: =IF(ISBLANK(Tableau142527[[#This Row],[Durée estimée3]]),"",Tableau142527[[#This Row],[Durée estimée3]]) | E14: =IF(ISBLANK(Tableau142527[[#This Row],[Durée estimée4]]),"",Tableau142527[[#This Row],[Durée estimée4]]) | F14: =SUM(Tableau132628[[#This Row],[Durée réelle en heures]:[Durée réelle en heures4]]) -> 0 | G14: =IF('Séance 5'!F14=0,0,IF('Séance 4'!F14=0,"Nouvelle tâche",(('Séance 5'!F14)/'Séance 4'!F14))) -> 0 | N14: =SUM(Tableau14252729[[#This Row],[Durée estimée]:[Durée estimée4]]) -> 0
... A23: =IF(ISBLANK(Tableau142527[[#This Row],[Description de la tâche]]),"",Tableau142527[[#This Row],[Description de la tâche]]) | B23: =IF(ISBLANK(Tableau142527[[#This Row],[Durée estimée]]),"",Tableau142527[[#This Row],[Durée estimée]]) | C23: =IF(ISBLANK(Tableau142527[[#This Row],[Durée estimée2]]),"",Tableau142527[[#This Row],[Durée estimée2]]) | D23: =IF(ISBLANK(Tableau142527[[#This Row],[Durée estimée3]]),"",Tableau142527[[#This Row],[Durée estimée3]]) | E23: =IF(ISBLANK(Tableau142527[[#This Row],[Durée estimée4]]),"",Tableau142527[[#This Row],[Durée estimée4]]) | F23: =SUM(Tableau132628[[#This Row],[Durée réelle en heures]:[Durée réelle en heures4]]) -> 0 | G23: =IF('Séance 5'!F23=0,0,IF('Séance 4'!F23=0,"Nouvelle tâche",(('Séance 5'!F23)/'Séance 4'!F23))) -> 0 | N23: =SUM(Tableau14252729[[#This Row],[Durée estimée]:[Durée estimée4]]) -> 0
A24: =IF(ISBLANK(Tableau142527[[#This Row],[Description de la tâche]]),"",Tableau142527[[#This Row],[Description de la tâche]]) | B24: =IF(ISBLANK(Tableau142527[[#This Row],[Durée estimée]]),"",Tableau142527[[#This Row],[Durée estimée]]) | C24: =IF(ISBLANK(Tableau142527[[#This Row],[Durée estimée2]]),"",Tableau142527[[#This Row],[Durée estimée2]]) | D24: =IF(ISBLANK(Tableau142527[[#This Row],[Durée estimée3]]),"",Tableau142527[[#This Row],[Durée estimée3]]) | E24: =IF(ISBLANK(Tableau142527[[#This Row],[Durée estimée4]]),"",Tableau142527[[#This Row],[Durée estimée4]]) | F24: =SUM(Tableau132628[[#This Row],[Durée réelle en heures]:[Durée réelle en heures4]]) -> 0 | G24: =IF('Séance 5'!F24=0,0,IF('Séance 4'!F25=0,"Nouvelle tâche",(('Séance 5'!F24)/'Séance 4'!F25))) -> 0 | N24: =SUM(Tableau14252729[[#This Row],[Durée estimée]:[Durée estimée4]]) -> 0
A25: =IF(ISBLANK(Tableau142527[[#This Row],[Description de la tâche]]),"",Tableau142527[[#This Row],[Description de la tâche]]) | B25: =IF(ISBLANK(Tableau142527[[#This Row],[Durée estimée]]),"",Tableau142527[[#This Row],[Durée estimée]]) | C25: =IF(ISBLANK(Tableau142527[[#This Row],[Durée estimée2]]),"",Tableau142527[[#This Row],[Durée estimée2]]) | D25: =IF(ISBLANK(Tableau142527[[#This Row],[Durée estimée3]]),"",Tableau142527[[#This Row],[Durée estimée3]]) | E25: =IF(ISBLANK(Tableau142527[[#This Row],[Durée estimée4]]),"",Tableau142527[[#This Row],[Durée estimée4]]) | F25: =SUM(Tableau132628[[#This Row],[Durée réelle en heures]:[Durée réelle en heures4]]) -> 0 | G25: =IF('Séance 5'!F25=0,0,IF('Séance 4'!F26=0,"Nouvelle tâche",(('Séance 5'!F25)/'Séance 4'!F26))) -> 0 | N25: =SUM(Tableau14252729[[#This Row],[Durée estimée]:[Durée estimée4]]) -> 0
A26: Volume global travaillé | B26: =SUM(B3:B25) -> 0 | C26: =SUM(C3:C25) -> 0 | D26: =SUM(D3:D25) -> 0 | E26: =SUM(E3:E25) -> 0 | F26: =SUM(F3:F25) -> 0 | G26: =SUM(Tableau132628[[#This Row],[Durée réelle en heures]:[Total réel]]) -> 0 | I26: Volume global prévu | J26: =SUM(J3:J25) -> 0 | K26: =SUM(K3:K25) -> 0 | L26: =SUM(L3:L25) -> 0 | M26: =SUM(M3:M25) -> 0 | N26: =SUM(N3:N25) -> 0
A27: Pourcentage global | B27: =IF($G$26=0,"Non renseigné",B26/$G$26*100) -> Non renseigné | C27: =IF($G$26=0,"Non renseigné",C26/$G$26*100) -> Non renseigné | D27: =IF($G$26=0,"Non renseigné",D26/$G$26*100) -> Non renseigné | E27: =IF($G$26=0,"Non renseigné",E26/$G$26*100) -> Non renseigné | F27: =SUM(Tableau132628[[#This Row],[Durée réelle en heures]:[Durée réelle en heures4]]) -> 0 | G27: =SUM(Tableau132628[[#This Row],[Durée réelle en heures]:[Total réel]]) -> 0 | I27: Pourcentage global prévu | J27: =IF($N$26=0,"Non renseigné",J26/$N$26*100) -> Non renseigné | K27: =IF($N$26=0,"Non renseigné",K26/$N$26*100) -> Non renseigné | L27: =IF($N$26=0,"Non renseigné",L26/$N$26*100) -> Non renseigné | M27: =IF($N$26=0,"Non renseigné",M26/$N$26*100) -> Non renseigné | N27: =SUM(Tableau14252729[[#This Row],[Durée estimée]:[Durée estimée4]]) -> 0

Sheet Séance 6
A1: Bilan des tâches réalisées | B1: =Synthèse!D2 -> Nom1 | C1: =Synthèse!D3 -> Nom2 | D1: =Synthèse!D4 -> Nom3 | E1: =Synthèse!D5 -> Nom4 | I1: Tâches prévues | J1: =Synthèse!$D2 -> Nom1 | K1: =Synthèse!$D3 -> Nom2 | L1: =Synthèse!$D4 -> Nom3 | M1: =Synthèse!$D5 -> Nom4
A2: Description de la tâche | B2: Durée réelle en heures | C2: Durée réelle en heures2 | D2: Durée réelle en heures3 | E2: Durée réelle en heures4 | F2: Total réel | G2: Ecart relatif entre prévisionnel et réel | I2: Description de la tâche | J2: Durée estimée | K2: Durée estimée2 | L2: Durée estimée3 | M2: Durée estimée4 | N2: Durée totale estimée (heures)
A3: =IF(ISBLANK(Tableau1425272912[[#This Row],[Description de la tâche]]),"",Tableau1425272912[[#This Row],[Description de la tâche]]) | B3: =IF(ISBLANK(Tableau1425272912[[#This Row],[Durée estimée]]),"",Tableau1425272912[[#This Row],[Durée estimée]]) | C3: =IF(ISBLANK(Tableau1425272912[[#This Row],[Durée estimée2]]),"",Tableau1425272912[[#This Row],[Durée estimée2]]) | D3: =IF(ISBLANK(Tableau1425272912[[#This Row],[Durée estimée3]]),"",Tableau1425272912[[#This Row],[Durée estimée3]]) | E3: =IF(ISBLANK(Tableau1425272912[[#This Row],[Durée estimée4]]),"",Tableau1425272912[[#This Row],[Durée estimée4]]) | F3: =SUM(Tableau13262811[[#This Row],[Durée réelle en heures]:[Durée réelle en heures4]]) -> 0 | G3: =IF('Séance 5'!F3=0,0,IF('Séance 4'!F3=0,"Nouvelle tâche",(('Séance 5'!F3)/'Séance 4'!F3))) -> 0 | N3: =SUM(Tableau1425272912[[#This Row],[Durée estimée]:[Durée estimée4]]) -> 0
A4: =IF(ISBLANK(Tableau1425272912[[#This Row],[Description de la tâche]]),"",Tableau1425272912[[#This Row],[Description de la tâche]]) | B4: =IF(ISBLANK(Tableau1425272912[[#This Row],[Durée estimée]]),"",Tableau1425272912[[#This Row],[Durée estimée]]) | C4: =IF(ISBLANK(Tableau1425272912[[#This Row],[Durée estimée2]]),"",Tableau1425272912[[#This Row],[Durée estimée2]]) | D4: =IF(ISBLANK(Tableau1425272912[[#This Row],[Durée estimée3]]),"",Tableau1425272912[[#This Row],[Durée estimée3]]) | E4: =IF(ISBLANK(Tableau1425272912[[#This Row],[Durée estimée4]]),"",Tableau1425272912[[#This Row],[Durée estimée4]]) | F4: =SUM(Tableau13262811[[#This Row],[Durée réelle en heures]:[Durée réelle en heures4]]) -> 0 | G4: =IF('Séance 5'!F4=0,0,IF('Séance 4'!F4=0,"Nouvelle tâche",(('Séance 5'!F4)/'Séance 4'!F4))) -> 0 | N4: =SUM(Tableau1425272912[[#This Row],[Durée estimée]:[Durée estimée4]]) -> 0
A5: =IF(ISBLANK(Tableau1425272912[[#This Row],[Description de la tâche]]),"",Tableau1425272912[[#This Row],[Description de la tâche]]) | B5: =IF(ISBLANK(Tableau1425272912[[#This Row],[Durée estimée]]),"",Tableau1425272912[[#This Row],[Durée estimée]]) | C5: =IF(ISBLANK(Tableau1425272912[[#This Row],[Durée estimée2]]),"",Tableau1425272912[[#This Row],[Durée estimée2]]) | D5: =IF(ISBLANK(Tableau1425272912[[#This Row],[Durée estimée3]]),"",Tableau1425272912[[#This Row],[Durée estimée3]]) | E5: =IF(ISBLANK(Tableau1425272912[[#This Row],[Durée estimée4]]),"",Tableau1425272912[[#This Row],[Durée estimée4]]) | F5: =SUM(Tableau13262811[[#This Row],[Durée réelle en heures]:[Durée réelle en heures4]]) -> 0 | G5: =IF('Séance 5'!F5=0,0,IF('Séance 4'!F5=0,"Nouvelle tâche",(('Séance 5'!F5)/'Séance 4'!F5))) -> 0 | N5: =SUM(Tableau1425272912[[#This Row],[Durée estimée]:[Durée estimée4]]) -> 0
A6: =IF(ISBLANK(Tableau1425272912[[#This Row],[Description de la tâche]]),"",Tableau1425272912[[#This Row],[Description de la tâche]]) | B6: =IF(ISBLANK(Tableau1425272912[[#This Row],[Durée estimée]]),"",Tableau1425272912[[#This Row],[Durée estimée]]) | C6: =IF(ISBLANK(Tableau1425272912[[#This Row],[Durée estimée2]]),"",Tableau1425272912[[#This Row],[Durée estimée2]]) | D6: =IF(ISBLANK(Tableau1425272912[[#This Row],[Durée estimée3]]),"",Tableau1425272912[[#This Row],[Durée estimée3]]) | E6: =IF(ISBLANK(Tableau1425272912[[#This Row],[Durée estimée4]]),"",Tableau1425272912[[#This Row],[Durée estimée4]]) | F6: =SUM(Tableau13262811[[#This Row],[Durée réelle en heures]:[Durée réelle en heures4]]) -> 0 | G6: =IF('Séance 5'!F6=0,0,IF('Séance 4'!F6=0,"Nouvelle tâche",(('Séance 5'!F6)/'Séance 4'!F6))) -> 0 | N6: =SUM(Tableau1425272912[[#This Row],[Durée estimée]:[Durée estimée4]]) -> 0
A7: =IF(ISBLANK(Tableau1425272912[[#This Row],[Description de la tâche]]),"",Tableau1425272912[[#This Row],[Description de la tâche]]) | B7: =IF(ISBLANK(Tableau1425272912[[#This Row],[Durée estimée]]),"",Tableau1425272912[[#This Row],[Durée estimée]]) | C7: =IF(ISBLANK(Tableau1425272912[[#This Row],[Durée estimée2]]),"",Tableau1425272912[[#This Row],[Durée estimée2]]) | D7: =IF(ISBLANK(Tableau1425272912[[#This Row],[Durée estimée3]]),"",Tableau1425272912[[#This Row],[Durée estimée3]]) | E7: =IF(ISBLANK(Tableau1425272912[[#This Row],[Durée estimée4]]),"",Tableau1425272912[[#This Row],[Durée estimée4]]) | F7: =SUM(Tableau13262811[[#This Row],[Durée réelle en heures]:[Durée réelle en heures4]]) -> 0 | G7: =IF('Séance 5'!F7=0,0,IF('Séance 4'!F7=0,"Nouvelle tâche",(('Séance 5'!F7)/'Séance 4'!F7))) -> 0 | N7: =SUM(Tableau1425272912[[#This Row],[Durée estimée]:[Durée estimée4]]) -> 0
A8: =IF(ISBLANK(Tableau1425272912[[#This Row],[Description de la tâche]]),"",Tableau1425272912[[#This Row],[Description de la tâche]]) | B8: =IF(ISBLANK(Tableau1425272912[[#This Row],[Durée estimée]]),"",Tableau1425272912[[#This Row],[Durée estimée]]) | C8: =IF(ISBLANK(Tableau1425272912[[#This Row],[Durée estimée2]]),"",Tableau1425272912[[#This Row],[Durée estimée2]]) | D8: =IF(ISBLANK(Tableau1425272912[[#This Row],[Durée estimée3]]),"",Tableau1425272912[[#This Row],[Durée estimée3]]) | E8: =IF(ISBLANK(Tableau1425272912[[#This Row],[Durée estimée4]]),"",Tableau1425272912[[#This Row],[Durée estimée4]]) | F8: =SUM(Tableau13262811[[#This Row],[Durée réelle en heures]:[Durée réelle en heures4]]) -> 0 | G8: =IF('Séance 5'!F8=0,0,IF('Séance 4'!F8=0,"Nouvelle tâche",(('Séance 5'!F8)/'Séance 4'!F8))) -> 0 | N8: =SUM(Tableau1425272912[[#This Row],[Durée estimée]:[Durée estimée4]]) -> 0
A9: =IF(ISBLANK(Tableau1425272912[[#This Row],[Description de la tâche]]),"",Tableau1425272912[[#This Row],[Description de la tâche]]) | B9: =IF(ISBLANK(Tableau1425272912[[#This Row],[Durée estimée]]),"",Tableau1425272912[[#This Row],[Durée estimée]]) | C9: =IF(ISBLANK(Tableau1425272912[[#This Row],[Durée estimée2]]),"",Tableau1425272912[[#This Row],[Durée estimée2]]) | D9: =IF(ISBLANK(Tableau1425272912[[#This Row],[Durée estimée3]]),"",Tableau1425272912[[#This Row],[Durée estimée3]]) | E9: =IF(ISBLANK(Tableau1425272912[[#This Row],[Durée estimée4]]),"",Tableau1425272912[[#This Row],[Durée estimée4]]) | F9: =SUM(Tableau13262811[[#This Row],[Durée réelle en heures]:[Durée réelle en heures4]]) -> 0 | G9: =IF('Séance 5'!F9=0,0,IF('Séance 4'!F9=0,"Nouvelle tâche",(('Séance 5'!F9)/'Séance 4'!F9))) -> 0 | N9: =SUM(Tableau1425272912[[#This Row],[Durée estimée]:[Durée estimée4]]) -> 0
A10: =IF(ISBLANK(Tableau1425272912[[#This Row],[Description de la tâche]]),"",Tableau1425272912[[#This Row],[Description de la tâche]]) | B10: =IF(ISBLANK(Tableau1425272912[[#This Row],[Durée estimée]]),"",Tableau1425272912[[#This Row],[Durée estimée]]) | C10: =IF(ISBLANK(Tableau1425272912[[#This Row],[Durée estimée2]]),"",Tableau1425272912[[#This Row],[Durée estimée2]]) | D10: =IF(ISBLANK(Tableau1425272912[[#This Row],[Durée estimée3]]),"",Tableau1425272912[[#This Row],[Durée estimée3]]) | E10: =IF(ISBLANK(Tableau1425272912[[#This Row],[Durée estimée4]]),"",Tableau1425272912[[#This Row],[Durée estimée4]]) | F10: =SUM(Tableau13262811[[#This Row],[Durée réelle en heures]:[Durée réelle en heures4]]) -> 0 | G10: =IF('Séance 5'!F10=0,0,IF('Séance 4'!F10=0,"Nouvelle tâche",(('Séance 5'!F10)/'Séance 4'!F10))) -> 0 | N10: =SUM(Tableau1425272912[[#This Row],[Durée estimée]:[Durée estimée4]]) -> 0
A11: =IF(ISBLANK(Tableau1425272912[[#This Row],[Description de la tâche]]),"",Tableau1425272912[[#This Row],[Description de la tâche]]) | B11: =IF(ISBLANK(Tableau1425272912[[#This Row],[Durée estimée]]),"",Tableau1425272912[[#This Row],[Durée estimée]]) | C11: =IF(ISBLANK(Tableau1425272912[[#This Row],[Durée estimée2]]),"",Tableau1425272912[[#This Row],[Durée estimée2]]) | D11: =IF(ISBLANK(Tableau1425272912[[#This Row],[Durée estimée3]]),"",Tableau1425272912[[#This Row],[Durée estimée3]]) | E11: =IF(ISBLANK(Tableau1425272912[[#This Row],[Durée estimée4]]),"",Tableau1425272912[[#This Row],[Durée estimée4]]) | F11: =SUM(Tableau13262811[[#This Row],[Durée réelle en heures]:[Durée réelle en heures4]]) -> 0 | G11: =IF('Séance 5'!F11=0,0,IF('Séance 4'!F11=0,"Nouvelle tâche",(('Séance 5'!F11)/'Séance 4'!F11))) -> 0 | N11: =SUM(Tableau1425272912[[#This Row],[Durée estimée]:[Durée estimée4]]) -> 0
A12: =IF(ISBLANK(Tableau1425272912[[#This Row],[Description de la tâche]]),"",Tableau1425272912[[#This Row],[Description de la tâche]]) | B12: =IF(ISBLANK(Tableau1425272912[[#This Row],[Durée estimée]]),"",Tableau1425272912[[#This Row],[Durée estimée]]) | C12: =IF(ISBLANK(Tableau1425272912[[#This Row],[Durée estimée2]]),"",Tableau1425272912[[#This Row],[Durée estimée2]]) | D12: =IF(ISBLANK(Tableau1425272912[[#This Row],[Durée estimée3]]),"",Tableau1425272912[[#This Row],[Durée estimée3]]) | E12: =IF(ISBLANK(Tableau1425272912[[#This Row],[Durée estimée4]]),"",Tableau1425272912[[#This Row],[Durée estimée4]]) | F12: =SUM(Tableau13262811[[#This Row],[Durée réelle en heures]:[Durée réelle en heures4]]) -> 0 | G12: =IF('Séance 5'!F12=0,0,IF('Séance 4'!F12=0,"Nouvelle tâche",(('Séance 5'!F12)/'Séance 4'!F12))) -> 0 | N12: =SUM(Tableau1425272912[[#This Row],[Durée estimée]:[Durée estimée4]]) -> 0
A13: =IF(ISBLANK(Tableau1425272912[[#This Row],[Description de la tâche]]),"",Tableau1425272912[[#This Row],[Description de la tâche]]) | B13: =IF(ISBLANK(Tableau1425272912[[#This Row],[Durée estimée]]),"",Tableau1425272912[[#This Row],[Durée estimée]]) | C13: =IF(ISBLANK(Tableau1425272912[[#This Row],[Durée estimée2]]),"",Tableau1425272912[[#This Row],[Durée estimée2]]) | D13: =IF(ISBLANK(Tableau1425272912[[#This Row],[Durée estimée3]]),"",Tableau1425272912[[#This Row],[Durée estimée3]]) | E13: =IF(ISBLANK(Tableau1425272912[[#This Row],[Durée estimée4]]),"",Tableau1425272912[[#This Row],[Durée estimée4]]) | F13: =SUM(Tableau13262811[[#This Row],[Durée réelle en heures]:[Durée réelle en heures4]]) -> 0 | G13: =IF('Séance 5'!F13=0,0,IF('Séance 4'!F13=0,"Nouvelle tâche",(('Séance 5'!F13)/'Séance 4'!F13))) -> 0 | N13: =SUM(Tableau1425272912[[#This Row],[Durée estimée]:[Durée estimée4]]) -> 0
A14: =IF(ISBLANK(Tableau1425272912[[#This Row],[Description de la tâche]]),"",Tableau1425272912[[#This Row],[Description de la tâche]]) | B14: =IF(ISBLANK(Tableau1425272912[[#This Row],[Durée estimée]]),"",Tableau1425272912[[#This Row],[Durée estimée]]) | C14: =IF(ISBLANK(Tableau1425272912[[#This Row],[Durée estimée2]]),"",Tableau1425272912[[#This Row],[Durée estimée2]]) | D14: =IF(ISBLANK(Tableau1425272912[[#This Row],[Durée estimée3]]),"",Tableau1425272912[[#This Row],[Durée estimée3]]) | E14: =IF(ISBLANK(Tableau1425272912[[#This Row],[Durée estimée4]]),"",Tableau1425272912[[#This Row],[Durée estimée4]]) | F14: =SUM(Tableau13262811[[#This Row],[Durée réelle en heures]:[Durée réelle en heures4]]) -> 0 | G14: =IF('Séance 5'!F14=0,0,IF('Séance 4'!F14=0,"Nouvelle tâche",(('Séance 5'!F14)/'Séance 4'!F14))) -> 0 | N14: =SUM(Tableau1425272912[[#This Row],[Durée estimée]:[Durée estimée4]]) -> 0
... A23: =IF(ISBLANK(Tableau1425272912[[#This Row],[Description de la tâche]]),"",Tableau1425272912[[#This Row],[Description de la tâche]]) | B23: =IF(ISBLANK(Tableau1425272912[[#This Row],[Durée estimée]]),"",Tableau1425272912[[#This Row],[Durée estimée]]) | C23: =IF(ISBLANK(Tableau1425272912[[#This Row],[Durée estimée2]]),"",Tableau1425272912[[#This Row],[Durée estimée2]]) | D23: =IF(ISBLANK(Tableau1425272912[[#This Row],[Durée estimée3]]),"",Tableau1425272912[[#This Row],[Durée estimée3]]) | E23: =IF(ISBLANK(Tableau1425272912[[#This Row],[Durée estimée4]]),"",Tableau1425272912[[#This Row],[Durée estimée4]]) | F23: =SUM(Tableau13262811[[#This Row],[Durée réelle en heures]:[Durée réelle en heures4]]) -> 0 | G23: =IF('Séance 5'!F23=0,0,IF('Séance 4'!F23=0,"Nouvelle tâche",(('Séance 5'!F23)/'Séance 4'!F23))) -> 0 | N23: =SUM(Tableau1425272912[[#This Row],[Durée estimée]:[Durée estimée4]]) -> 0
A24: =IF(ISBLANK(Tableau1425272912[[#This Row],[Description de la tâche]]),"",Tableau1425272912[[#This Row],[Description de la tâche]]) | B24: =IF(ISBLANK(Tableau1425272912[[#This Row],[Durée estimée]]),"",Tableau1425272912[[#This Row],[Durée estimée]]) | C24: =IF(ISBLANK(Tableau1425272912[[#This Row],[Durée estimée2]]),"",Tableau1425272912[[#This Row],[Durée estimée2]]) | D24: =IF(ISBLANK(Tableau1425272912[[#This Row],[Durée estimée3]]),"",Tableau1425272912[[#This Row],[Durée estimée3]]) | E24: =IF(ISBLANK(Tableau1425272912[[#This Row],[Durée estimée4]]),"",Tableau1425272912[[#This Row],[Durée estimée4]]) | F24: =SUM(Tableau13262811[[#This Row],[Durée réelle en heures]:[Durée réelle en heures4]]) -> 0 | G24: =IF('Séance 5'!F24=0,0,IF('Séance 4'!F25=0,"Nouvelle tâche",(('Séance 5'!F24)/'Séance 4'!F25))) -> 0 | N24: =SUM(Tableau1425272912[[#This Row],[Durée estimée]:[Durée estimée4]]) -> 0
A25: =IF(ISBLANK(Tableau1425272912[[#This Row],[Description de la tâche]]),"",Tableau1425272912[[#This Row],[Description de la tâche]]) | B25: =IF(ISBLANK(Tableau1425272912[[#This Row],[Durée estimée]]),"",Tableau1425272912[[#This Row],[Durée estimée]]) | C25: =IF(ISBLANK(Tableau1425272912[[#This Row],[Durée estimée2]]),"",Tableau1425272912[[#This Row],[Durée estimée2]]) | D25: =IF(ISBLANK(Tableau1425272912[[#This Row],[Durée estimée3]]),"",Tableau1425272912[[#This Row],[Durée estimée3]]) | E25: =IF(ISBLANK(Tableau1425272912[[#This Row],[Durée estimée4]]),"",Tableau1425272912[[#This Row],[Durée estimée4]]) | F25: =SUM(Tableau13262811[[#This Row],[Durée réelle en heures]:[Durée réelle en heures4]]) -> 0 | G25: =IF('Séance 5'!F25=0,0,IF('Séance 4'!F26=0,"Nouvelle tâche",(('Séance 5'!F25)/'Séance 4'!F26))) -> 0 | N25: =SUM(Tableau1425272912[[#This Row],[Durée estimée]:[Durée estimée4]]) -> 0
A26: Volume global travaillé | B26: =SUM(B3:B25) -> 0 | C26: =SUM(C3:C25) -> 0 | D26: =SUM(D3:D25) -> 0 | E26: =SUM(E3:E25) -> 0 | F26: =SUM(F3:F25) -> 0 | G26: =SUM(Tableau13262811[[#This Row],[Durée réelle en heures]:[Total réel]]) -> 0 | I26: Volume global prévu | J26: =SUM(J3:J25) -> 0 | K26: =SUM(K3:K25) -> 0 | L26: =SUM(L3:L25) -> 0 | M26: =SUM(M3:M25) -> 0 | N26: =SUM(N3:N25) -> 0
A27: Pourcentage global | B27: =IF($G$26=0,"Non renseigné",B26/$G$26*100) -> Non renseigné | C27: =IF($G$26=0,"Non renseigné",C26/$G$26*100) -> Non renseigné | D27: =IF($G$26=0,"Non renseigné",D26/$G$26*100) -> Non renseigné | E27: =IF($G$26=0,"Non renseigné",E26/$G$26*100) -> Non renseigné | F27: =SUM(Tableau13262811[[#This Row],[Durée réelle en heures]:[Durée réelle en heures4]]) -> 0 | G27: =SUM(Tableau13262811[[#This Row],[Durée réelle en heures]:[Total réel]]) -> 0 | I27: Pourcentage global prévu | J27: =IF($N$26=0,"Non renseigné",J26/$N$26*100) -> Non renseigné | K27: =IF($N$26=0,"Non renseigné",K26/$N$26*100) -> Non renseigné | L27: =IF($N$26=0,"Non renseigné",L26/$N$26*100) -> Non renseigné | M27: =IF($N$26=0,"Non renseigné",M26/$N$26*100) -> Non renseigné | N27: =SUM(Tableau1425272912[[#This Row],[Durée estimée]:[Durée estimée4]]) -> 0

Sheet Séance 7
A1: Bilan des tâches réalisées | B1: =Synthèse!D2 -> Nom1 | C1: =Synthèse!D3 -> Nom2 | D1: =Synthèse!D4 -> Nom3 | E1: =Synthèse!D5 -> Nom4 | I1: Tâches prévues | J1: =Synthèse!$D2 -> Nom1 | K1: =Synthèse!$D3 -> Nom2 | L1: =Synthèse!$D4 -> Nom3 | M1: =Synthèse!$D5 -> Nom4
A2: Description de la tâche | B2: Durée réelle en heures | C2: Durée réelle en heures2 | D2: Durée réelle en heures3 | E2: Durée réelle en heures4 | F2: Total réel | G2: Ecart relatif entre prévisionnel et réel | I2: Description de la tâche | J2: Durée estimée | K2: Durée estimée2 | L2: Durée estimée3 | M2: Durée estimée4 | N2: Durée totale estimée (heures)
A3: =IF(ISBLANK(Tableau1425272912[[#This Row],[Description de la tâche]]),"",Tableau1425272912[[#This Row],[Description de la tâche]]) | B3: =IF(ISBLANK(Tableau1425272912[[#This Row],[Durée estimée]]),"",Tableau1425272912[[#This Row],[Durée estimée]]) | C3: =IF(ISBLANK(Tableau1425272912[[#This Row],[Durée estimée2]]),"",Tableau1425272912[[#This Row],[Durée estimée2]]) | D3: =IF(ISBLANK(Tableau1425272912[[#This Row],[Durée estimée3]]),"",Tableau1425272912[[#This Row],[Durée estimée3]]) | E3: =IF(ISBLANK(Tableau1425272912[[#This Row],[Durée estimée4]]),"",Tableau1425272912[[#This Row],[Durée estimée4]]) | F3: =SUM(Tableau13262813[[#This Row],[Durée réelle en heures]:[Durée réelle en heures4]]) -> 0 | G3: =IF('Séance 5'!F3=0,0,IF('Séance 4'!F3=0,"Nouvelle tâche",(('Séance 5'!F3)/'Séance 4'!F3))) -> 0 | N3: =SUM(Tableau1425272914[[#This Row],[Durée estimée]:[Durée estimée4]]) -> 0
A4: =IF(ISBLANK(Tableau1425272912[[#This Row],[Description de la tâche]]),"",Tableau1425272912[[#This Row],[Description de la tâche]]) | B4: =IF(ISBLANK(Tableau1425272912[[#This Row],[Durée estimée]]),"",Tableau1425272912[[#This Row],[Durée estimée]]) | C4: =IF(ISBLANK(Tableau1425272912[[#This Row],[Durée estimée2]]),"",Tableau1425272912[[#This Row],[Durée estimée2]]) | D4: =IF(ISBLANK(Tableau1425272912[[#This Row],[Durée estimée3]]),"",Tableau1425272912[[#This Row],[Durée estimée3]]) | E4: =IF(ISBLANK(Tableau1425272912[[#This Row],[Durée estimée4]]),"",Tableau1425272912[[#This Row],[Durée estimée4]]) | F4: =SUM(Tableau13262813[[#This Row],[Durée réelle en heures]:[Durée réelle en heures4]]) -> 0 | G4: =IF('Séance 5'!F4=0,0,IF('Séance 4'!F4=0,"Nouvelle tâche",(('Séance 5'!F4)/'Séance 4'!F4))) -> 0 | N4: =SUM(Tableau1425272914[[#This Row],[Durée estimée]:[Durée estimée4]]) -> 0
A5: =IF(ISBLANK(Tableau1425272912[[#This Row],[Description de la tâche]]),"",Tableau1425272912[[#This Row],[Description de la tâche]]) | B5: =IF(ISBLANK(Tableau1425272912[[#This Row],[Durée estimée]]),"",Tableau1425272912[[#This Row],[Durée estimée]]) | C5: =IF(ISBLANK(Tableau1425272912[[#This Row],[Durée estimée2]]),"",Tableau1425272912[[#This Row],[Durée estimée2]]) | D5: =IF(ISBLANK(Tableau1425272912[[#This Row],[Durée estimée3]]),"",Tableau1425272912[[#This Row],[Durée estimée3]]) | E5: =IF(ISBLANK(Tableau1425272912[[#This Row],[Durée estimée4]]),"",Tableau1425272912[[#This Row],[Durée estimée4]]) | F5: =SUM(Tableau13262813[[#This Row],[Durée réelle en heures]:[Durée réelle en heures4]]) -> 0 | G5: =IF('Séance 5'!F5=0,0,IF('Séance 4'!F5=0,"Nouvelle tâche",(('Séance 5'!F5)/'Séance 4'!F5))) -> 0 | N5: =SUM(Tableau1425272914[[#This Row],[Durée estimée]:[Durée estimée4]]) -> 0
A6: =IF(ISBLANK(Tableau1425272912[[#This Row],[Description de la tâche]]),"",Tableau1425272912[[#This Row],[Description de la tâche]]) | B6: =IF(ISBLANK(Tableau1425272912[[#This Row],[Durée estimée]]),"",Tableau1425272912[[#This Row],[Durée estimée]]) | C6: =IF(ISBLANK(Tableau1425272912[[#This Row],[Durée estimée2]]),"",Tableau1425272912[[#This Row],[Durée estimée2]]) | D6: =IF(ISBLANK(Tableau1425272912[[#This Row],[Durée estimée3]]),"",Tableau1425272912[[#This Row],[Durée estimée3]]) | E6: =IF(ISBLANK(Tableau1425272912[[#This Row],[Durée estimée4]]),"",Tableau1425272912[[#This Row],[Durée estimée4]]) | F6: =SUM(Tableau13262813[[#This Row],[Durée réelle en heures]:[Durée réelle en heures4]]) -> 0 | G6: =IF('Séance 5'!F6=0,0,IF('Séance 4'!F6=0,"Nouvelle tâche",(('Séance 5'!F6)/'Séance 4'!F6))) -> 0 | N6: =SUM(Tableau1425272914[[#This Row],[Durée estimée]:[Durée estimée4]]) -> 0
A7: =IF(ISBLANK(Tableau1425272912[[#This Row],[Description de la tâche]]),"",Tableau1425272912[[#This Row],[Description de la tâche]]) | B7: =IF(ISBLANK(Tableau1425272912[[#This Row],[Durée estimée]]),"",Tableau1425272912[[#This Row],[Durée estimée]]) | C7: =IF(ISBLANK(Tableau1425272912[[#This Row],[Durée estimée2]]),"",Tableau1425272912[[#This Row],[Durée estimée2]]) | D7: =IF(ISBLANK(Tableau1425272912[[#This Row],[Durée estimée3]]),"",Tableau1425272912[[#This Row],[Durée estimée3]]) | E7: =IF(ISBLANK(Tableau1425272912[[#This Row],[Durée estimée4]]),"",Tableau1425272912[[#This Row],[Durée estimée4]]) | F7: =SUM(Tableau13262813[[#This Row],[Durée réelle en heures]:[Durée réelle en heures4]]) -> 0 | G7: =IF('Séance 5'!F7=0,0,IF('Séance 4'!F7=0,"Nouvelle tâche",(('Séance 5'!F7)/'Séance 4'!F7))) -> 0 | N7: =SUM(Tableau1425272914[[#This Row],[Durée estimée]:[Durée estimée4]]) -> 0
A8: =IF(ISBLANK(Tableau1425272912[[#This Row],[Description de la tâche]]),"",Tableau1425272912[[#This Row],[Description de la tâche]]) | B8: =IF(ISBLANK(Tableau1425272912[[#This Row],[Durée estimée]]),"",Tableau1425272912[[#This Row],[Durée estimée]]) | C8: =IF(ISBLANK(Tableau1425272912[[#This Row],[Durée estimée2]]),"",Tableau1425272912[[#This Row],[Durée estimée2]]) | D8: =IF(ISBLANK(Tableau1425272912[[#This Row],[Durée estimée3]]),"",Tableau1425272912[[#This Row],[Durée estimée3]]) | E8: =IF(ISBLANK(Tableau1425272912[[#This Row],[Durée estimée4]]),"",Tableau1425272912[[#This Row],[Durée estimée4]]) | F8: =SUM(Tableau13262813[[#This Row],[Durée réelle en heures]:[Durée réelle en heures4]]) -> 0 | G8: =IF('Séance 5'!F8=0,0,IF('Séance 4'!F8=0,"Nouvelle tâche",(('Séance 5'!F8)/'Séance 4'!F8))) -> 0 | N8: =SUM(Tableau1425272914[[#This Row],[Durée estimée]:[Durée estimée4]]) -> 0
A9: =IF(ISBLANK(Tableau1425272912[[#This Row],[Description de la tâche]]),"",Tableau1425272912[[#This Row],[Description de la tâche]]) | B9: =IF(ISBLANK(Tableau1425272912[[#This Row],[Durée estimée]]),"",Tableau1425272912[[#This Row],[Durée estimée]]) | C9: =IF(ISBLANK(Tableau1425272912[[#This Row],[Durée estimée2]]),"",Tableau1425272912[[#This Row],[Durée estimée2]]) | D9: =IF(ISBLANK(Tableau1425272912[[#This Row],[Durée estimée3]]),"",Tableau1425272912[[#This Row],[Durée estimée3]]) | E9: =IF(ISBLANK(Tableau1425272912[[#This Row],[Durée estimée4]]),"",Tableau1425272912[[#This Row],[Durée estimée4]]) | F9: =SUM(Tableau13262813[[#This Row],[Durée réelle en heures]:[Durée réelle en heures4]]) -> 0 | G9: =IF('Séance 5'!F9=0,0,IF('Séance 4'!F9=0,"Nouvelle tâche",(('Séance 5'!F9)/'Séance 4'!F9))) -> 0 | N9: =SUM(Tableau1425272914[[#This Row],[Durée estimée]:[Durée estimée4]]) -> 0
A10: =IF(ISBLANK(Tableau1425272912[[#This Row],[Description de la tâche]]),"",Tableau1425272912[[#This Row],[Description de la tâche]]) | B10: =IF(ISBLANK(Tableau1425272912[[#This Row],[Durée estimée]]),"",Tableau1425272912[[#This Row],[Durée estimée]]) | C10: =IF(ISBLANK(Tableau1425272912[[#This Row],[Durée estimée2]]),"",Tableau1425272912[[#This Row],[Durée estimée2]]) | D10: =IF(ISBLANK(Tableau1425272912[[#This Row],[Durée estimée3]]),"",Tableau1425272912[[#This Row],[Durée estimée3]]) | E10: =IF(ISBLANK(Tableau1425272912[[#This Row],[Durée estimée4]]),"",Tableau1425272912[[#This Row],[Durée estimée4]]) | F10: =SUM(Tableau13262813[[#This Row],[Durée réelle en heures]:[Durée réelle en heures4]]) -> 0 | G10: =IF('Séance 5'!F10=0,0,IF('Séance 4'!F10=0,"Nouvelle tâche",(('Séance 5'!F10)/'Séance 4'!F10))) -> 0 | N10: =SUM(Tableau1425272914[[#This Row],[Durée estimée]:[Durée estimée4]]) -> 0
A11: =IF(ISBLANK(Tableau1425272912[[#This Row],[Description de la tâche]]),"",Tableau1425272912[[#This Row],[Description de la tâche]]) | B11: =IF(ISBLANK(Tableau1425272912[[#This Row],[Durée estimée]]),"",Tableau1425272912[[#This Row],[Durée estimée]]) | C11: =IF(ISBLANK(Tableau1425272912[[#This Row],[Durée estimée2]]),"",Tableau1425272912[[#This Row],[Durée estimée2]]) | D11: =IF(ISBLANK(Tableau1425272912[[#This Row],[Durée estimée3]]),"",Tableau1425272912[[#This Row],[Durée estimée3]]) | E11: =IF(ISBLANK(Tableau1425272912[[#This Row],[Durée estimée4]]),"",Tableau1425272912[[#This Row],[Durée estimée4]]) | F11: =SUM(Tableau13262813[[#This Row],[Durée réelle en heures]:[Durée réelle en heures4]]) -> 0 | G11: =IF('Séance 5'!F11=0,0,IF('Séance 4'!F11=0,"Nouvelle tâche",(('Séance 5'!F11)/'Séance 4'!F11))) -> 0 | N11: =SUM(Tableau1425272914[[#This Row],[Durée estimée]:[Durée estimée4]]) -> 0
A12: =IF(ISBLANK(Tableau1425272912[[#This Row],[Description de la tâche]]),"",Tableau1425272912[[#This Row],[Description de la tâche]]) | B12: =IF(ISBLANK(Tableau1425272912[[#This Row],[Durée estimée]]),"",Tableau1425272912[[#This Row],[Durée estimée]]) | C12: =IF(ISBLANK(Tableau1425272912[[#This Row],[Durée estimée2]]),"",Tableau1425272912[[#This Row],[Durée estimée2]]) | D12: =IF(ISBLANK(Tableau1425272912[[#This Row],[Durée estimée3]]),"",Tableau1425272912[[#This Row],[Durée estimée3]]) | E12: =IF(ISBLANK(Tableau1425272912[[#This Row],[Durée estimée4]]),"",Tableau1425272912[[#This Row],[Durée estimée4]]) | F12: =SUM(Tableau13262813[[#This Row],[Durée réelle en heures]:[Durée réelle en heures4]]) -> 0 | G12: =IF('Séance 5'!F12=0,0,IF('Séance 4'!F12=0,"Nouvelle tâche",(('Séance 5'!F12)/'Séance 4'!F12))) -> 0 | N12: =SUM(Tableau1425272914[[#This Row],[Durée estimée]:[Durée estimée4]]) -> 0
A13: =IF(ISBLANK(Tableau1425272912[[#This Row],[Description de la tâche]]),"",Tableau1425272912[[#This Row],[Description de la tâche]]) | B13: =IF(ISBLANK(Tableau1425272912[[#This Row],[Durée estimée]]),"",Tableau1425272912[[#This Row],[Durée estimée]]) | C13: =IF(ISBLANK(Tableau1425272912[[#This Row],[Durée estimée2]]),"",Tableau1425272912[[#This Row],[Durée estimée2]]) | D13: =IF(ISBLANK(Tableau1425272912[[#This Row],[Durée estimée3]]),"",Tableau1425272912[[#This Row],[Durée estimée3]]) | E13: =IF(ISBLANK(Tableau1425272912[[#This Row],[Durée estimée4]]),"",Tableau1425272912[[#This Row],[Durée estimée4]]) | F13: =SUM(Tableau13262813[[#This Row],[Durée réelle en heures]:[Durée réelle en heures4]]) -> 0 | G13: =IF('Séance 5'!F13=0,0,IF('Séance 4'!F13=0,"Nouvelle tâche",(('Séance 5'!F13)/'Séance 4'!F13))) -> 0 | N13: =SUM(Tableau1425272914[[#This Row],[Durée estimée]:[Durée estimée4]]) -> 0
A14: =IF(ISBLANK(Tableau1425272912[[#This Row],[Description de la tâche]]),"",Tableau1425272912[[#This Row],[Description de la tâche]]) | B14: =IF(ISBLANK(Tableau1425272912[[#This Row],[Durée estimée]]),"",Tableau1425272912[[#This Row],[Durée estimée]]) | C14: =IF(ISBLANK(Tableau1425272912[[#This Row],[Durée estimée2]]),"",Tableau1425272912[[#This Row],[Durée estimée2]]) | D14: =IF(ISBLANK(Tableau1425272912[[#This Row],[Durée estimée3]]),"",Tableau1425272912[[#This Row],[Durée estimée3]]) | E14: =IF(ISBLANK(Tableau1425272912[[#This Row],[Durée estimée4]]),"",Tableau1425272912[[#This Row],[Durée estimée4]]) | F14: =SUM(Tableau13262813[[#This Row],[Durée réelle en heures]:[Durée réelle en heures4]]) -> 0 | G14: =IF('Séance 5'!F14=0,0,IF('Séance 4'!F14=0,"Nouvelle tâche",(('Séance 5'!F14)/'Séance 4'!F14))) -> 0 | N14: =SUM(Tableau1425272914[[#This Row],[Durée estimée]:[Durée estimée4]]) -> 0
... A23: =IF(ISBLANK(Tableau1425272912[[#This Row],[Description de la tâche]]),"",Tableau1425272912[[#This Row],[Description de la tâche]]) | B23: =IF(ISBLANK(Tableau1425272912[[#This Row],[Durée estimée]]),"",Tableau1425272912[[#This Row],[Durée estimée]]) | C23: =IF(ISBLANK(Tableau1425272912[[#This Row],[Durée estimée2]]),"",Tableau1425272912[[#This Row],[Durée estimée2]]) | D23: =IF(ISBLANK(Tableau1425272912[[#This Row],[Durée estimée3]]),"",Tableau1425272912[[#This Row],[Durée estimée3]]) | E23: =IF(ISBLANK(Tableau1425272912[[#This Row],[Durée estimée4]]),"",Tableau1425272912[[#This Row],[Durée estimée4]]) | F23: =SUM(Tableau13262813[[#This Row],[Durée réelle en heures]:[Durée réelle en heures4]]) -> 0 | G23: =IF('Séance 5'!F23=0,0,IF('Séance 4'!F23=0,"Nouvelle tâche",(('Séance 5'!F23)/'Séance 4'!F23))) -> 0 | N23: =SUM(Tableau1425272914[[#This Row],[Durée estimée]:[Durée estimée4]]) -> 0
A24: =IF(ISBLANK(Tableau1425272912[[#This Row],[Description de la tâche]]),"",Tableau1425272912[[#This Row],[Description de la tâche]]) | B24: =IF(ISBLANK(Tableau1425272912[[#This Row],[Durée estimée]]),"",Tableau1425272912[[#This Row],[Durée estimée]]) | C24: =IF(ISBLANK(Tableau1425272912[[#This Row],[Durée estimée2]]),"",Tableau1425272912[[#This Row],[Durée estimée2]]) | D24: =IF(ISBLANK(Tableau1425272912[[#This Row],[Durée estimée3]]),"",Tableau1425272912[[#This Row],[Durée estimée3]]) | E24: =IF(ISBLANK(Tableau1425272912[[#This Row],[Durée estimée4]]),"",Tableau1425272912[[#This Row],[Durée estimée4]]) | F24: =SUM(Tableau13262813[[#This Row],[Durée réelle en heures]:[Durée réelle en heures4]]) -> 0 | G24: =IF('Séance 5'!F24=0,0,IF('Séance 4'!F25=0,"Nouvelle tâche",(('Séance 5'!F24)/'Séance 4'!F25))) -> 0 | N24: =SUM(Tableau1425272914[[#This Row],[Durée estimée]:[Durée estimée4]]) -> 0
A25: =IF(ISBLANK(Tableau1425272912[[#This Row],[Description de la tâche]]),"",Tableau1425272912[[#This Row],[Description de la tâche]]) | B25: =IF(ISBLANK(Tableau1425272912[[#This Row],[Durée estimée]]),"",Tableau1425272912[[#This Row],[Durée estimée]]) | C25: =IF(ISBLANK(Tableau1425272912[[#This Row],[Durée estimée2]]),"",Tableau1425272912[[#This Row],[Durée estimée2]]) | D25: =IF(ISBLANK(Tableau1425272912[[#This Row],[Durée estimée3]]),"",Tableau1425272912[[#This Row],[Durée estimée3]]) | E25: =IF(ISBLANK(Tableau1425272912[[#This Row],[Durée estimée4]]),"",Tableau1425272912[[#This Row],[Durée estimée4]]) | F25: =SUM(Tableau13262813[[#This Row],[Durée réelle en heures]:[Durée réelle en heures4]]) -> 0 | G25: =IF('Séance 5'!F25=0,0,IF('Séance 4'!F26=0,"Nouvelle tâche",(('Séance 5'!F25)/'Séance 4'!F26))) -> 0 | N25: =SUM(Tableau1425272914[[#This Row],[Durée estimée]:[Durée estimée4]]) -> 0
A26: Volume global travaillé | B26: =SUM(B3:B25) -> 0 | C26: =SUM(C3:C25) -> 0 | D26: =SUM(D3:D25) -> 0 | E26: =SUM(E3:E25) -> 0 | F26: =SUM(F3:F25) -> 0 | G26: =SUM(Tableau13262813[[#This Row],[Durée réelle en heures]:[Total réel]]) -> 0 | I26: Volume global prévu | J26: =SUM(J3:J25) -> 0 | K26: =SUM(K3:K25) -> 0 | L26: =SUM(L3:L25) -> 0 | M26: =SUM(M3:M25) -> 0 | N26: =SUM(N3:N25) -> 0
A27: Pourcentage global | B27: =IF($G$26=0,"Non renseigné",B26/$G$26*100) -> Non renseigné | C27: =IF($G$26=0,"Non renseigné",C26/$G$26*100) -> Non renseigné | D27: =IF($G$26=0,"Non renseigné",D26/$G$26*100) -> Non renseigné | E27: =IF($G$26=0,"Non renseigné",E26/$G$26*100) -> Non renseigné | F27: =SUM(Tableau13262813[[#This Row],[Durée réelle en heures]:[Durée réelle en heures4]]) -> 0 | G27: =SUM(Tableau13262813[[#This Row],[Durée réelle en heures]:[Total réel]]) -> 0 | I27: Pourcentage global prévu | J27: =IF($N$26=0,"Non renseigné",J26/$N$26*100) -> Non renseigné | K27: =IF($N$26=0,"Non renseigné",K26/$N$26*100) -> Non renseigné | L27: =IF($N$26=0,"Non renseigné",L26/$N$26*100) -> Non renseigné | M27: =IF($N$26=0,"Non renseigné",M26/$N$26*100) -> Non renseigné | N27: =SUM(Tableau1425272914[[#This Row],[Durée estimée]:[Durée estimée4]]) -> 0

Sheet Séance 8
A1: Bilan des tâches réalisées | B1: =Synthèse!D2 -> Nom1 | C1: =Synthèse!D3 -> Nom2 | D1: =Synthèse!D4 -> Nom3 | E1: =Synthèse!D5 -> Nom4 | I1: Tâches prévues | J1: =Synthèse!$D2 -> Nom1 | K1: =Synthèse!$D3 -> Nom2 | L1: =Synthèse!$D4 -> Nom3 | M1: =Synthèse!$D5 -> Nom4
A2: Description de la tâche | B2: Durée réelle en heures | C2: Durée réelle en heures2 | D2: Durée réelle en heures3 | E2: Durée réelle en heures4 | F2: Total réel | G2: Ecart relatif entre prévisionnel et réel | I2: Description de la tâche | J2: Durée estimée | K2: Durée estimée2 | L2: Durée estimée3 | M2: Durée estimée4 | N2: Durée totale estimée (heures)
A3: =IF(ISBLANK(Tableau1425272914[[#This Row],[Description de la tâche]]),"",Tableau1425272914[[#This Row],[Description de la tâche]]) | B3: =IF(ISBLANK(Tableau1425272914[[#This Row],[Durée estimée]]),"",Tableau1425272914[[#This Row],[Durée estimée]]) | C3: =IF(ISBLANK(Tableau1425272914[[#This Row],[Durée estimée2]]),"",Tableau1425272914[[#This Row],[Durée estimée2]]) | D3: =IF(ISBLANK(Tableau1425272914[[#This Row],[Durée estimée3]]),"",Tableau1425272914[[#This Row],[Durée estimée3]]) | E3: =IF(ISBLANK(Tableau1425272914[[#This Row],[Durée estimée4]]),"",Tableau1425272914[[#This Row],[Durée estimée4]]) | F3: =SUM(Tableau13262815[[#This Row],[Durée réelle en heures]:[Durée réelle en heures4]]) -> 0 | G3: =IF('Séance 5'!F3=0,0,IF('Séance 4'!F3=0,"Nouvelle tâche",(('Séance 5'!F3)/'Séance 4'!F3))) -> 0 | N3: =SUM(Tableau1425272916[[#This Row],[Durée estimée]:[Durée estimée4]]) -> 0
A4: =IF(ISBLANK(Tableau1425272914[[#This Row],[Description de la tâche]]),"",Tableau1425272914[[#This Row],[Description de la tâche]]) | B4: =IF(ISBLANK(Tableau1425272914[[#This Row],[Durée estimée]]),"",Tableau1425272914[[#This Row],[Durée estimée]]) | C4: =IF(ISBLANK(Tableau1425272914[[#This Row],[Durée estimée2]]),"",Tableau1425272914[[#This Row],[Durée estimée2]]) | D4: =IF(ISBLANK(Tableau1425272914[[#This Row],[Durée estimée3]]),"",Tableau1425272914[[#This Row],[Durée estimée3]]) | E4: =IF(ISBLANK(Tableau1425272914[[#This Row],[Durée estimée4]]),"",Tableau1425272914[[#This Row],[Durée estimée4]]) | F4: =SUM(Tableau13262815[[#This Row],[Durée réelle en heures]:[Durée réelle en heures4]]) -> 0 | G4: =IF('Séance 5'!F4=0,0,IF('Séance 4'!F4=0,"Nouvelle tâche",(('Séance 5'!F4)/'Séance 4'!F4))) -> 0 | N4: =SUM(Tableau1425272916[[#This Row],[Durée estimée]:[Durée estimée4]]) -> 0
A5: =IF(ISBLANK(Tableau1425272914[[#This Row],[Description de la tâche]]),"",Tableau1425272914[[#This Row],[Description de la tâche]]) | B5: =IF(ISBLANK(Tableau1425272914[[#This Row],[Durée estimée]]),"",Tableau1425272914[[#This Row],[Durée estimée]]) | C5: =IF(ISBLANK(Tableau1425272914[[#This Row],[Durée estimée2]]),"",Tableau1425272914[[#This Row],[Durée estimée2]]) | D5: =IF(ISBLANK(Tableau1425272914[[#This Row],[Durée estimée3]]),"",Tableau1425272914[[#This Row],[Durée estimée3]]) | E5: =IF(ISBLANK(Tableau1425272914[[#This Row],[Durée estimée4]]),"",Tableau1425272914[[#This Row],[Durée estimée4]]) | F5: =SUM(Tableau13262815[[#This Row],[Durée réelle en heures]:[Durée réelle en heures4]]) -> 0 | G5: =IF('Séance 5'!F5=0,0,IF('Séance 4'!F5=0,"Nouvelle tâche",(('Séance 5'!F5)/'Séance 4'!F5))) -> 0 | N5: =SUM(Tableau1425272916[[#This Row],[Durée estimée]:[Durée estimée4]]) -> 0
A6: =IF(ISBLANK(Tableau1425272914[[#This Row],[Description de la tâche]]),"",Tableau1425272914[[#This Row],[Description de la tâche]]) | B6: =IF(ISBLANK(Tableau1425272914[[#This Row],[Durée estimée]]),"",Tableau1425272914[[#This Row],[Durée estimée]]) | C6: =IF(ISBLANK(Tableau1425272914[[#This Row],[Durée estimée2]]),"",Tableau1425272914[[#This Row],[Durée estimée2]]) | D6: =IF(ISBLANK(Tableau1425272914[[#This Row],[Durée estimée3]]),"",Tableau1425272914[[#This Row],[Durée estimée3]]) | E6: =IF(ISBLANK(Tableau1425272914[[#This Row],[Durée estimée4]]),"",Tableau1425272914[[#This Row],[Durée estimée4]]) | F6: =SUM(Tableau13262815[[#This Row],[Durée réelle en heures]:[Durée réelle en heures4]]) -> 0 | G6: =IF('Séance 5'!F6=0,0,IF('Séance 4'!F6=0,"Nouvelle tâche",(('Séance 5'!F6)/'Séance 4'!F6))) -> 0 | N6: =SUM(Tableau1425272916[[#This Row],[Durée estimée]:[Durée estimée4]]) -> 0
A7: =IF(ISBLANK(Tableau1425272914[[#This Row],[Description de la tâche]]),"",Tableau1425272914[[#This Row],[Description de la tâche]]) | B7: =IF(ISBLANK(Tableau1425272914[[#This Row],[Durée estimée]]),"",Tableau1425272914[[#This Row],[Durée estimée]]) | C7: =IF(ISBLANK(Tableau1425272914[[#This Row],[Durée estimée2]]),"",Tableau1425272914[[#This Row],[Durée estimée2]]) | D7: =IF(ISBLANK(Tableau1425272914[[#This Row],[Durée estimée3]]),"",Tableau1425272914[[#This Row],[Durée estimée3]]) | E7: =IF(ISBLANK(Tableau1425272914[[#This Row],[Durée estimée4]]),"",Tableau1425272914[[#This Row],[Durée estimée4]]) | F7: =SUM(Tableau13262815[[#This Row],[Durée réelle en heures]:[Durée réelle en heures4]]) -> 0 | G7: =IF('Séance 5'!F7=0,0,IF('Séance 4'!F7=0,"Nouvelle tâche",(('Séance 5'!F7)/'Séance 4'!F7))) -> 0 | N7: =SUM(Tableau1425272916[[#This Row],[Durée estimée]:[Durée estimée4]]) -> 0
A8: =IF(ISBLANK(Tableau1425272914[[#This Row],[Description de la tâche]]),"",Tableau1425272914[[#This Row],[Description de la tâche]]) | B8: =IF(ISBLANK(Tableau1425272914[[#This Row],[Durée estimée]]),"",Tableau1425272914[[#This Row],[Durée estimée]]) | C8: =IF(ISBLANK(Tableau1425272914[[#This Row],[Durée estimée2]]),"",Tableau1425272914[[#This Row],[Durée estimée2]]) | D8: =IF(ISBLANK(Tableau1425272914[[#This Row],[Durée estimée3]]),"",Tableau1425272914[[#This Row],[Durée estimée3]]) | E8: =IF(ISBLANK(Tableau1425272914[[#This Row],[Durée estimée4]]),"",Tableau1425272914[[#This Row],[Durée estimée4]]) | F8: =SUM(Tableau13262815[[#This Row],[Durée réelle en heures]:[Durée réelle en heures4]]) -> 0 | G8: =IF('Séance 5'!F8=0,0,IF('Séance 4'!F8=0,"Nouvelle tâche",(('Séance 5'!F8)/'Séance 4'!F8))) -> 0 | N8: =SUM(Tableau1425272916[[#This Row],[Durée estimée]:[Durée estimée4]]) -> 0
A9: =IF(ISBLANK(Tableau1425272914[[#This Row],[Description de la tâche]]),"",Tableau1425272914[[#This Row],[Description de la tâche]]) | B9: =IF(ISBLANK(Tableau1425272914[[#This Row],[Durée estimée]]),"",Tableau1425272914[[#This Row],[Durée estimée]]) | C9: =IF(ISBLANK(Tableau1425272914[[#This Row],[Durée estimée2]]),"",Tableau1425272914[[#This Row],[Durée estimée2]]) | D9: =IF(ISBLANK(Tableau1425272914[[#This Row],[Durée estimée3]]),"",Tableau1425272914[[#This Row],[Durée estimée3]]) | E9: =IF(ISBLANK(Tableau1425272914[[#This Row],[Durée estimée4]]),"",Tableau1425272914[[#This Row],[Durée estimée4]]) | F9: =SUM(Tableau13262815[[#This Row],[Durée réelle en heures]:[Durée réelle en heures4]]) -> 0 | G9: =IF('Séance 5'!F9=0,0,IF('Séance 4'!F9=0,"Nouvelle tâche",(('Séance 5'!F9)/'Séance 4'!F9))) -> 0 | N9: =SUM(Tableau1425272916[[#This Row],[Durée estimée]:[Durée estimée4]]) -> 0
A10: =IF(ISBLANK(Tableau1425272914[[#This Row],[Description de la tâche]]),"",Tableau1425272914[[#This Row],[Description de la tâche]]) | B10: =IF(ISBLANK(Tableau1425272914[[#This Row],[Durée estimée]]),"",Tableau1425272914[[#This Row],[Durée estimée]]) | C10: =IF(ISBLANK(Tableau1425272914[[#This Row],[Durée estimée2]]),"",Tableau1425272914[[#This Row],[Durée estimée2]]) | D10: =IF(ISBLANK(Tableau1425272914[[#This Row],[Durée estimée3]]),"",Tableau1425272914[[#This Row],[Durée estimée3]]) | E10: =IF(ISBLANK(Tableau1425272914[[#This Row],[Durée estimée4]]),"",Tableau1425272914[[#This Row],[Durée estimée4]]) | F10: =SUM(Tableau13262815[[#This Row],[Durée réelle en heures]:[Durée réelle en heures4]]) -> 0 | G10: =IF('Séance 5'!F10=0,0,IF('Séance 4'!F10=0,"Nouvelle tâche",(('Séance 5'!F10)/'Séance 4'!F10))) -> 0 | N10: =SUM(Tableau1425272916[[#This Row],[Durée estimée]:[Durée estimée4]]) -> 0
